2023-09-23 18:43:56,833 - instabot version: 0.117.0 (bot) - INFO - Instabot version: 0.117.0 Started
2023-09-23 18:43:56,833 - instabot version: 0.117.0 (bot) - DEBUG - Bot imported from /Library/Frameworks/Python.framework/Versions/3.11/lib/python3.11/site-packages/instabot/bot/bot.py
2023-09-23 18:43:56,834 - instabot version: 0.117.0 (api_login) - INFO - Not yet logged in starting: PRE-LOGIN FLOW!
2023-09-23 18:45:11,848 - instabot version: 0.117.0 (api) - WARNING - HTTPSConnectionPool(host='i.instagram.com', port=443): Max retries exceeded with url: /api/v1/accounts/get_prefill_candidates/ (Caused by ConnectTimeoutError(<urllib3.connection.HTTPSConnection object at 0x10241f250>, 'Connection to i.instagram.com timed out. (connect timeout=None)'))
2023-09-23 18:46:33,019 - instabot version: 0.117.0 (api) - WARNING - HTTPSConnectionPool(host='i.instagram.com', port=443): Max retries exceeded with url: /api/v1/qe/sync/ (Caused by ConnectTimeoutError(<urllib3.connection.HTTPSConnection object at 0x1024357d0>, 'Connection to i.instagram.com timed out. (connect timeout=None)'))
2023-09-23 18:46:33,026 - instabot version: 0.117.0 (api) - WARNING - HTTPSConnectionPool(host='i.instagram.com', port=443): Max retries exceeded with url: /api/v1/launcher/sync/ (Caused by NameResolutionError("<urllib3.connection.HTTPSConnection object at 0x102437c90>: Failed to resolve 'i.instagram.com' ([Errno 8] nodename nor servname provided, or not known)"))
2023-09-23 18:46:33,031 - instabot version: 0.117.0 (api) - WARNING - HTTPSConnectionPool(host='i.instagram.com', port=443): Max retries exceeded with url: /api/v1/accounts/contact_point_prefill/ (Caused by NameResolutionError("<urllib3.connection.HTTPSConnection object at 0x10243e110>: Failed to resolve 'i.instagram.com' ([Errno 8] nodename nor servname provided, or not known)"))
